2019-07-19 23:36:48,395 [ERROR]  Exception occurred while handling uri: 'http://localhost:5005/'
Traceback (most recent call last):
  File "/Users/dinmohameddanabek/miniconda3/envs/weather-bot/lib/python3.7/site-packages/sanic/app.py", line 893, in handle_request
    handler, args, kwargs, uri = self.router.get(request)
  File "/Users/dinmohameddanabek/miniconda3/envs/weather-bot/lib/python3.7/site-packages/sanic/router.py", line 407, in get
    return self._get(request.path, request.method, "")
  File "/Users/dinmohameddanabek/miniconda3/envs/weather-bot/lib/python3.7/site-packages/sanic/router.py", line 469, in _get
    raise NotFound("Requested URL {} not found".format(url))
sanic.exceptions.NotFound: Requested URL / not found
2019-07-22 21:42:45,817 [ERROR]  Exception occurred while handling uri: 'http://80e4324f.ngrok.io/'
Traceback (most recent call last):
  File "/Users/dinmohameddanabek/miniconda3/envs/weather-bot/lib/python3.7/site-packages/sanic/app.py", line 893, in handle_request
    handler, args, kwargs, uri = self.router.get(request)
  File "/Users/dinmohameddanabek/miniconda3/envs/weather-bot/lib/python3.7/site-packages/sanic/router.py", line 407, in get
    return self._get(request.path, request.method, "")
  File "/Users/dinmohameddanabek/miniconda3/envs/weather-bot/lib/python3.7/site-packages/sanic/router.py", line 469, in _get
    raise NotFound("Requested URL {} not found".format(url))
sanic.exceptions.NotFound: Requested URL / not found
2019-07-22 21:42:46,314 [ERROR]  Exception occurred while handling uri: 'http://80e4324f.ngrok.io/favicon.ico'
Traceback (most recent call last):
  File "/Users/dinmohameddanabek/miniconda3/envs/weather-bot/lib/python3.7/site-packages/sanic/app.py", line 893, in handle_request
    handler, args, kwargs, uri = self.router.get(request)
  File "/Users/dinmohameddanabek/miniconda3/envs/weather-bot/lib/python3.7/site-packages/sanic/router.py", line 407, in get
    return self._get(request.path, request.method, "")
  File "/Users/dinmohameddanabek/miniconda3/envs/weather-bot/lib/python3.7/site-packages/sanic/router.py", line 469, in _get
    raise NotFound("Requested URL {} not found".format(url))
sanic.exceptions.NotFound: Requested URL /favicon.ico not found
2019-07-22 21:42:48,660 [ERROR]  Exception occurred while handling uri: 'http://80e4324f.ngrok.io/'
Traceback (most recent call last):
  File "/Users/dinmohameddanabek/miniconda3/envs/weather-bot/lib/python3.7/site-packages/sanic/app.py", line 893, in handle_request
    handler, args, kwargs, uri = self.router.get(request)
  File "/Users/dinmohameddanabek/miniconda3/envs/weather-bot/lib/python3.7/site-packages/sanic/router.py", line 407, in get
    return self._get(request.path, request.method, "")
  File "/Users/dinmohameddanabek/miniconda3/envs/weather-bot/lib/python3.7/site-packages/sanic/router.py", line 469, in _get
    raise NotFound("Requested URL {} not found".format(url))
sanic.exceptions.NotFound: Requested URL / not found
2019-07-22 21:44:50,326 [ERROR]  Exception occurred while handling uri: 'http://80e4324f.ngrok.io/'
Traceback (most recent call last):
  File "/Users/dinmohameddanabek/miniconda3/envs/weather-bot/lib/python3.7/site-packages/sanic/app.py", line 893, in handle_request
    handler, args, kwargs, uri = self.router.get(request)
  File "/Users/dinmohameddanabek/miniconda3/envs/weather-bot/lib/python3.7/site-packages/sanic/router.py", line 407, in get
    return self._get(request.path, request.method, "")
  File "/Users/dinmohameddanabek/miniconda3/envs/weather-bot/lib/python3.7/site-packages/sanic/router.py", line 469, in _get
    raise NotFound("Requested URL {} not found".format(url))
sanic.exceptions.NotFound: Requested URL / not found
2019-07-22 21:44:51,861 [ERROR]  Exception occurred while handling uri: 'http://80e4324f.ngrok.io/'
Traceback (most recent call last):
  File "/Users/dinmohameddanabek/miniconda3/envs/weather-bot/lib/python3.7/site-packages/sanic/app.py", line 893, in handle_request
    handler, args, kwargs, uri = self.router.get(request)
  File "/Users/dinmohameddanabek/miniconda3/envs/weather-bot/lib/python3.7/site-packages/sanic/router.py", line 407, in get
    return self._get(request.path, request.method, "")
  File "/Users/dinmohameddanabek/miniconda3/envs/weather-bot/lib/python3.7/site-packages/sanic/router.py", line 469, in _get
    raise NotFound("Requested URL {} not found".format(url))
sanic.exceptions.NotFound: Requested URL / not found
2019-07-22 21:47:09,770 [ERROR]  Exception occurred while handling uri: 'http://a717f7ca.ngrok.io/'
Traceback (most recent call last):
  File "/Users/dinmohameddanabek/miniconda3/envs/weather-bot/lib/python3.7/site-packages/sanic/app.py", line 893, in handle_request
    handler, args, kwargs, uri = self.router.get(request)
  File "/Users/dinmohameddanabek/miniconda3/envs/weather-bot/lib/python3.7/site-packages/sanic/router.py", line 407, in get
    return self._get(request.path, request.method, "")
  File "/Users/dinmohameddanabek/miniconda3/envs/weather-bot/lib/python3.7/site-packages/sanic/router.py", line 469, in _get
    raise NotFound("Requested URL {} not found".format(url))
sanic.exceptions.NotFound: Requested URL / not found
2019-07-22 21:57:23,994 [ERROR]  Exception occurred while handling uri: 'http://bdf2d496.ngrok.io/'
Traceback (most recent call last):
  File "/Users/dinmohameddanabek/miniconda3/envs/weather-bot/lib/python3.7/site-packages/sanic/app.py", line 893, in handle_request
    handler, args, kwargs, uri = self.router.get(request)
  File "/Users/dinmohameddanabek/miniconda3/envs/weather-bot/lib/python3.7/site-packages/sanic/router.py", line 407, in get
    return self._get(request.path, request.method, "")
  File "/Users/dinmohameddanabek/miniconda3/envs/weather-bot/lib/python3.7/site-packages/sanic/router.py", line 469, in _get
    raise NotFound("Requested URL {} not found".format(url))
sanic.exceptions.NotFound: Requested URL / not found
2019-07-22 21:57:58,157 [ERROR]  Exception occurred while handling uri: 'http://bdf2d496.ngrok.io/slack/webhook'
Traceback (most recent call last):
  File "/Users/dinmohameddanabek/miniconda3/envs/weather-bot/lib/python3.7/site-packages/sanic/app.py", line 893, in handle_request
    handler, args, kwargs, uri = self.router.get(request)
  File "/Users/dinmohameddanabek/miniconda3/envs/weather-bot/lib/python3.7/site-packages/sanic/router.py", line 407, in get
    return self._get(request.path, request.method, "")
  File "/Users/dinmohameddanabek/miniconda3/envs/weather-bot/lib/python3.7/site-packages/sanic/router.py", line 469, in _get
    raise NotFound("Requested URL {} not found".format(url))
sanic.exceptions.NotFound: Requested URL /slack/webhook not found
2019-07-22 21:57:59,832 [ERROR]  Exception occurred while handling uri: 'http://bdf2d496.ngrok.io/slack/webhook'
Traceback (most recent call last):
  File "/Users/dinmohameddanabek/miniconda3/envs/weather-bot/lib/python3.7/site-packages/sanic/app.py", line 893, in handle_request
    handler, args, kwargs, uri = self.router.get(request)
  File "/Users/dinmohameddanabek/miniconda3/envs/weather-bot/lib/python3.7/site-packages/sanic/router.py", line 407, in get
    return self._get(request.path, request.method, "")
  File "/Users/dinmohameddanabek/miniconda3/envs/weather-bot/lib/python3.7/site-packages/sanic/router.py", line 469, in _get
    raise NotFound("Requested URL {} not found".format(url))
sanic.exceptions.NotFound: Requested URL /slack/webhook not found
2019-07-22 21:58:07,205 [ERROR]  Exception occurred while handling uri: 'http://bdf2d496.ngrok.io/slack/events'
Traceback (most recent call last):
  File "/Users/dinmohameddanabek/miniconda3/envs/weather-bot/lib/python3.7/site-packages/sanic/app.py", line 893, in handle_request
    handler, args, kwargs, uri = self.router.get(request)
  File "/Users/dinmohameddanabek/miniconda3/envs/weather-bot/lib/python3.7/site-packages/sanic/router.py", line 407, in get
    return self._get(request.path, request.method, "")
  File "/Users/dinmohameddanabek/miniconda3/envs/weather-bot/lib/python3.7/site-packages/sanic/router.py", line 469, in _get
    raise NotFound("Requested URL {} not found".format(url))
sanic.exceptions.NotFound: Requested URL /slack/events not found
2019-07-22 22:02:07,537 [ERROR]  Exception occurred while handling uri: 'http://bdf2d496.ngrok.io/'
Traceback (most recent call last):
  File "/Users/dinmohameddanabek/miniconda3/envs/weather-bot/lib/python3.7/site-packages/sanic/app.py", line 893, in handle_request
    handler, args, kwargs, uri = self.router.get(request)
  File "/Users/dinmohameddanabek/miniconda3/envs/weather-bot/lib/python3.7/site-packages/sanic/router.py", line 407, in get
    return self._get(request.path, request.method, "")
  File "/Users/dinmohameddanabek/miniconda3/envs/weather-bot/lib/python3.7/site-packages/sanic/router.py", line 469, in _get
    raise NotFound("Requested URL {} not found".format(url))
sanic.exceptions.NotFound: Requested URL / not found
2019-07-22 23:15:02,448 [INFO ]  Starting Rasa server on http://localhost:5005
2019-07-22 23:15:17,088 [INFO ]  Added 'SpacyNLP' to component cache. Key 'SpacyNLP-en'.
2019-07-22 23:15:36,657 [ERROR]  Encountered an exception while running action 'action_weather'. Bot will continue, but the actions events are lost. Make sure to fix the exception in your custom code.
2019-07-22 23:16:56,721 [INFO ]  Killing Sanic server now.
2019-07-22 23:18:00,591 [INFO ]  Starting Rasa server on http://localhost:5005
2019-07-22 23:18:20,508 [INFO ]  Added 'SpacyNLP' to component cache. Key 'SpacyNLP-en'.
2019-07-22 23:18:48,176 [ERROR]  Encountered an exception while running action 'action_weather'. Bot will continue, but the actions events are lost. Make sure to fix the exception in your custom code.
2019-07-22 23:21:01,242 [INFO ]  Killing Sanic server now.
